Workbook

Sheet Summary
A1: Total | F1: Costs
B2: 1 Year | C2: 3 Years | D2: 10 Years | G2: 1 Year | H2: 3 Years | I2: 10 Years
A3: Profit - Higher Costs | B3: =B9+B15+B21+B27 -> -2.4711232e+09 | C3: =C9+C15+C21+C27 -> -7.5651794e+09 | D3: =D9+D15+D21+D27 -> -2.5037172e+10 | F3: Higher Costs | G3: ='Aggregate Projection'!O6*(1/((1+B32)^1)) -> 1.7247667e+10 | H3: ='Aggregate Projection'!Q6*(1/((1+B34)^3)) -> 1.8119646e+10 | I3: ='Aggregate Projection'!X6*(1/((1+B41)^10)) -> 1.9731022e+10
A4: Profit - Average Costs | B4: =B10+B16+B22+B28 -> 1.4540134e+08 | C4: =C10+C16+C22+C28 -> 4.5441168e+08 | D4: =D10+D16+D22+D28 -> 1.6201591e+09 | F4: Average Costs | G4: ='Aggregate Projection'!C6*(1/((1+B32)^1)) -> 1.4654047e+10 | H4: ='Aggregate Projection'!E6*(1/((1+B34)^3)) -> 1.539491e+10 | I4: ='Aggregate Projection'!L6*(1/((1+B41)^10)) -> 1.6763998e+10
A5: Profit – Lower Costs | B5: =B11+B17+B23+B29 -> 3.210154e+09 | C5: =C11+C17+C23+C29 -> 9.8477968e+09 | D5: =D11+D17+D23+D29 -> 3.2843853e+10 | F5: Lower Costs | G5: ='Aggregate Projection'!AA6*(1/((1+B32)^1)) -> 1.1616123e+10 | H5: ='Aggregate Projection'!AC6*(1/((1+B34)^3)) -> 1.2203417e+10 | I5: ='Aggregate Projection'!AJ6*(1/((1+B41)^10)) -> 1.3288746e+10
A7: Business Interruption
B8: 1 Year | C8: 3 Years | D8: 10 Years
A9: Higher Costs | B9: ='Business Interruption'!C28*(1/((1+B32)^1)) -> -8354696.7 | C9: ='Business Interruption'!E28*(1/((1+B34)^3)) -> -25631960 | D9: ='Business Interruption'!L28*(1/((1+B41)^10)) -> -85461229
A10: Average Costs | B10: ='Business Interruption'!C9*(1/((1+B32)^1)) -> 164598.28 | C10: ='Business Interruption'!E9*(1/((1+B34)^3)) -> 503957.44 | D10: ='Business Interruption'!L9*(1/((1+B41)^10)) -> 1676300.6
A11: Lower Costs | B11: ='Business Interruption'!C19*(1/((1+B32)^1)) -> 6163769.2 | C11: ='Business Interruption'!E19*(1/((1+B34)^3)) -> 18908513 | D11: ='Business Interruption'!L19*(1/((1+B41)^10)) -> 63037356
A13: Equipment Failure
B14: 1 Year | C14: 3 Years | D14: 10 Years
A15: Higher Costs | B15: ='Equipment Failure'!C28*(1/((1+B32)^1)) -> -4672508.3 | C15: ='Equipment Failure'!E28*(1/((1+B34)^3)) -> -14351896 | D15: ='Equipment Failure'!L28*(1/((1+B41)^10)) -> -47916718
A16: Average Costs | B16: ='Equipment Failure'!C9*(1/((1+B32)^1)) -> 2327630.6 | C16: ='Equipment Failure'!E9*(1/((1+B34)^3)) -> 7123479.1 | D16: ='Equipment Failure'!L9*(1/((1+B41)^10)) -> 23682494
A17: Lower Costs | B17: ='Equipment Failure'!C19*(1/((1+B32)^1)) -> 9154003.8 | C17: ='Equipment Failure'!E19*(1/((1+B34)^3)) -> 28065767 | D17: ='Equipment Failure'!L19*(1/((1+B41)^10)) -> 93504385
A19: Worker's Compensation
B20: 1 Year | C20: 3 Years | D20: 10 Years
A21: Higher Costs | B21: ='Workers Compensation'!C27*(1/((1+B32)^1)) -> -8418999 | C21: ='Workers Compensation'!E27*(1/((1+B34)^3)) -> -25788959 | D21: ='Workers Compensation'!L27*(1/((1+B41)^10)) -> -85534736
A22: Average Costs | B22: ='Workers Compensation'!C18*(1/((1+B32)^1)) -> 70727.091 | C22: ='Workers Compensation'!E18*(1/((1+B34)^3)) -> 231722.87 | D22: ='Workers Compensation'!L18*(1/((1+B41)^10)) -> 957141.4
A23: Lower Costs | B23: ='Workers Compensation'!C9*(1/((1+B32)^1)) -> 8409789.5 | C23: ='Workers Compensation'!E9*(1/((1+B34)^3)) -> 25790626 | D23: ='Workers Compensation'!L9*(1/((1+B41)^10)) -> 85914083
A25: Cargo Loss
B26: 1 Year | C26: 3 Years | D26: 10 Years
A27: Higher Costs | B27: ='Cargo Loss'!C27*(1/((1+B32)^1)) -> -2.449677e+09 | C27: ='Cargo Loss'!E27*(1/((1+B34)^3)) -> -7.4994066e+09 | D27: ='Cargo Loss'!L27*(1/((1+B41)^10)) -> -2.481826e+10
A28: Average Costs | B28: ='Cargo Loss'!C18*(1/((1+B32)^1)) -> 1.4283839e+08 | C28: ='Cargo Loss'!E18*(1/((1+B34)^3)) -> 4.4655252e+08 | D28: ='Cargo Loss'!L18*(1/((1+B41)^10)) -> 1.5938432e+09
A29: Lower Costs | B29: ='Cargo Loss'!C9*(1/((1+B32)^1)) -> 3.1864264e+09 | C29: ='Cargo Loss'!E9*(1/((1+B34)^3)) -> 9.7750319e+09 | D29: ='Cargo Loss'!L9*(1/((1+B41)^10)) -> 3.2601398e+10
A31: Year | B31: Yield curve
A32: 1 | B32: 0.017740256
A33: 2 | B33: 0.01903981
A34: 3 | B34: 0.020320031
A35: 4 | B35: 0.021586841
A36: 5 | B36: 0.022844226
A37: 6 | B37: 0.024094896
A38: 7 | B38: 0.025340714
A39: 8 | B39: 0.026582973
A40: 9 | B40: 0.027822583
A41: 10 | B41: 0.029060193

Sheet Aggregate Projection
A1: Expected Costs | C1: 2175 | D1: 2176 | E1: 2177 | N1: Upper Bound Costs / Lower Bound Profit | Z1: Lower Bound Costs / Upper Bound Profit
C2: 1 | D2: 2 | E2: 3 | F2: 4 | G2: 5 | H2: 6 | I2: 7 | J2: 8 | K2: 9 | L2: 10 | O2: 1 | P2: 2 | Q2: 3 | R2: 4 | S2: 5 | T2: 6 | U2: 7 | V2: 8 | W2: 9 | X2: 10 | AA2: 1 | AB2: 2 | AC2: 3 | AD2: 4 | AE2: 5 | AF2: 6 | AG2: 7 | AH2: 8 | AI2: 9 | AJ2: 10
A3: Retained Earnings | C3: ='Business Interruption'!C3+'Equipment Failure'!C3+'Workers Compensation'!C12+'Cargo Loss'!C12 -> 0 | D3: ='Business Interruption'!D3+'Equipment Failure'!D3+'Workers Compensation'!D12+'Cargo Loss'!D12 -> 1.479808e+08 | E3: ='Business Interruption'!E3+'Equipment Failure'!E3+'Workers Compensation'!E12+'Cargo Loss'!E12 -> 3.0852748e+08 | F3: ='Business Interruption'!F3+'Equipment Failure'!F3+'Workers Compensation'!F12+'Cargo Loss'!F12 -> 4.8267936e+08 | G3: ='Business Interruption'!G3+'Equipment Failure'!G3+'Workers Compensation'!G12+'Cargo Loss'!G12 -> 6.7136845e+08 | H3: ='Business Interruption'!H3+'Equipment Failure'!H3+'Workers Compensation'!H12+'Cargo Loss'!H12 -> 8.7547352e+08 | I3: ='Business Interruption'!I3+'Equipment Failure'!I3+'Workers Compensation'!I12+'Cargo Loss'!I12 -> 1.0958535e+09 | J3: ='Business Interruption'!J3+'Equipment Failure'!J3+'Workers Compensation'!J12+'Cargo Loss'!J12 -> 1.333368e+09 | ... L3: ='Business Interruption'!L3+'Equipment Failure'!L3+'Workers Compensation'!L12+'Cargo Loss'!L12 -> 1.8633177e+09 | N3: Retained Earnings | O3: ='Business Interruption'!C22+'Equipment Failure'!C22+'Workers Compensation'!C21+'Cargo Loss'!C21 -> 0 | P3: ='Business Interruption'!D22+'Equipment Failure'!D22+'Workers Compensation'!D21+'Cargo Loss'!D21 -> -2.5149615e+09 | Q3: ='Business Interruption'!E22+'Equipment Failure'!E22+'Workers Compensation'!E21+'Cargo Loss'!E21 -> -5.1910145e+09 | R3: ='Business Interruption'!F22+'Equipment Failure'!F22+'Workers Compensation'!F21+'Cargo Loss'!F21 -> -8.035788e+09 | S3: ='Business Interruption'!G22+'Equipment Failure'!G22+'Workers Compensation'!G21+'Cargo Loss'!G21 -> -1.1056926e+10 | T3: ='Business Interruption'!H22+'Equipment Failure'!H22+'Workers Compensation'!H21+'Cargo Loss'!H21 -> -1.4262227e+10 | U3: ='Business Interruption'!I22+'Equipment Failure'!I22+'Workers Compensation'!I21+'Cargo Loss'!I21 -> -1.7659716e+10 | V3: ='Business Interruption'!J22+'Equipment Failure'!J22+'Workers Compensation'!J21+'Cargo Loss'!J21 -> -2.1257691e+10 | ... X3: ='Business Interruption'!L22+'Equipment Failure'!L22+'Workers Compensation'!L21+'Cargo Loss'!L21 -> -2.9089808e+10 | Z3: Retained Earnings | AA3: ='Business Interruption'!C13+'Equipment Failure'!C13+'Workers Compensation'!C3+'Cargo Loss'!C3 -> 0 | AB3: ='Business Interruption'!D13+'Equipment Failure'!D13+'Workers Compensation'!D3+'Cargo Loss'!D3 -> 3.2671029e+09 | AC3: ='Business Interruption'!E13+'Equipment Failure'!E13+'Workers Compensation'!E3+'Cargo Loss'!E3 -> 6.7501725e+09 | AD3: ='Business Interruption'!F13+'Equipment Failure'!F13+'Workers Compensation'!F3+'Cargo Loss'!F3 -> 1.0460401e+10 | AE3: ='Business Interruption'!G13+'Equipment Failure'!G13+'Workers Compensation'!G3+'Cargo Loss'!G3 -> 1.4408765e+10 | AF3: ='Business Interruption'!H13+'Equipment Failure'!H13+'Workers Compensation'!H3+'Cargo Loss'!H3 -> 1.8606306e+10 | AG3: ='Business Interruption'!I13+'Equipment Failure'!I13+'Workers Compensation'!I3+'Cargo Loss'!I3 -> 2.306429e+10 | AH3: ='Business Interruption'!J13+'Equipment Failure'!J13+'Workers Compensation'!J3+'Cargo Loss'!J3 -> 2.7794301e+10 | ... AJ3: ='Business Interruption'!L13+'Equipment Failure'!L13+'Workers Compensation'!L3+'Cargo Loss'!L3 -> 3.8118696e+10
A4: Premium Revenue (Inflation + Exposure) | C4: ='Business Interruption'!C4+'Equipment Failure'!C4+'Workers Compensation'!C13+'Cargo Loss'!C13 -> 14928860354 | D4: ='Business Interruption'!D4+'Equipment Failure'!D4+'Workers Compensation'!D13+'Cargo Loss'!D13 -> 1.5636155e+10 | E4: ='Business Interruption'!E4+'Equipment Failure'!E4+'Workers Compensation'!E13+'Cargo Loss'!E13 -> 1.6373269e+10 | F4: ='Business Interruption'!F4+'Equipment Failure'!F4+'Workers Compensation'!F13+'Cargo Loss'!F13 -> 1.7139815e+10 | G4: ='Business Interruption'!G4+'Equipment Failure'!G4+'Workers Compensation'!G13+'Cargo Loss'!G13 -> 1.7935912e+10 | H4: ='Business Interruption'!H4+'Equipment Failure'!H4+'Workers Compensation'!H13+'Cargo Loss'!H13 -> 1.8762005e+10 | I4: ='Business Interruption'!I4+'Equipment Failure'!I4+'Workers Compensation'!I13+'Cargo Loss'!I13 -> 1.9618752e+10 | J4: ='Business Interruption'!J4+'Equipment Failure'!J4+'Workers Compensation'!J13+'Cargo Loss'!J13 -> 2.0506958e+10 | ... L4: ='Business Interruption'!L4+'Equipment Failure'!L4+'Workers Compensation'!L13+'Cargo Loss'!L13 -> 2.2381442e+10 | N4: Premium Revenue (Inflation + Exposure) | O4: ='Business Interruption'!C23+'Equipment Failure'!C23+'Workers Compensation'!C22+'Cargo Loss'!C22 -> 14928860354 | P4: ='Business Interruption'!D23+'Equipment Failure'!D23+'Workers Compensation'!D22+'Cargo Loss'!D22 -> 1.5636155e+10 | Q4: ='Business Interruption'!E23+'Equipment Failure'!E23+'Workers Compensation'!E22+'Cargo Loss'!E22 -> 1.6373269e+10 | R4: ='Business Interruption'!F23+'Equipment Failure'!F23+'Workers Compensation'!F22+'Cargo Loss'!F22 -> 1.7139815e+10 | S4: ='Business Interruption'!G23+'Equipment Failure'!G23+'Workers Compensation'!G22+'Cargo Loss'!G22 -> 1.7935912e+10 | T4: ='Business Interruption'!H23+'Equipment Failure'!H23+'Workers Compensation'!H22+'Cargo Loss'!H22 -> 1.8762005e+10 | U4: ='Business Interruption'!I23+'Equipment Failure'!I23+'Workers Compensation'!I22+'Cargo Loss'!I22 -> 1.9618752e+10 | V4: ='Business Interruption'!J23+'Equipment Failure'!J23+'Workers Compensation'!J22+'Cargo Loss'!J22 -> 2.0506958e+10 | ... X4: ='Business Interruption'!L23+'Equipment Failure'!L23+'Workers Compensation'!L22+'Cargo Loss'!L22 -> 2.2381442e+10 | Z4: Premium Revenue (Inflation + Exposure) | AA4: ='Business Interruption'!C14+'Equipment Failure'!C14+'Workers Compensation'!C4+'Cargo Loss'!C4 -> 14928860354 | AB4: ='Business Interruption'!D14+'Equipment Failure'!D14+'Workers Compensation'!D4+'Cargo Loss'!D4 -> 1.5636155e+10 | AC4: ='Business Interruption'!E14+'Equipment Failure'!E14+'Workers Compensation'!E4+'Cargo Loss'!E4 -> 1.6373269e+10 | AD4: ='Business Interruption'!F14+'Equipment Failure'!F14+'Workers Compensation'!F4+'Cargo Loss'!F4 -> 1.7139815e+10 | AE4: ='Business Interruption'!G14+'Equipment Failure'!G14+'Workers Compensation'!G4+'Cargo Loss'!G4 -> 1.7935912e+10 | AF4: ='Business Interruption'!H14+'Equipment Failure'!H14+'Workers Compensation'!H4+'Cargo Loss'!H4 -> 1.8762005e+10 | AG4: ='Business Interruption'!I14+'Equipment Failure'!I14+'Workers Compensation'!I4+'Cargo Loss'!I4 -> 1.9618752e+10 | AH4: ='Business Interruption'!J14+'Equipment Failure'!J14+'Workers Compensation'!J4+'Cargo Loss'!J4 -> 2.0506958e+10 | ... AJ4: ='Business Interruption'!L14+'Equipment Failure'!L14+'Workers Compensation'!L4+'Cargo Loss'!L4 -> 2.2381442e+10
A5: Interest on Premium and Retained Profit | C5: ='Business Interruption'!C5+'Equipment Failure'!C5+'Workers Compensation'!C14+'Cargo Loss'!C14 -> 1.3183876e+08 | D5: ='Business Interruption'!D5+'Equipment Failure'!D5+'Workers Compensation'!D14+'Cargo Loss'!D14 -> 1.4050294e+08 | E5: ='Business Interruption'!E5+'Equipment Failure'!E5+'Workers Compensation'!E14+'Cargo Loss'!E14 -> 1.4918826e+08 | F5: ='Business Interruption'!F5+'Equipment Failure'!F5+'Workers Compensation'!F14+'Cargo Loss'!F14 -> 1.5803533e+08 | G5: ='Business Interruption'!G5+'Equipment Failure'!G5+'Workers Compensation'!G14+'Cargo Loss'!G14 -> 1.6713799e+08 | H5: ='Business Interruption'!H5+'Equipment Failure'!H5+'Workers Compensation'!H14+'Cargo Loss'!H14 -> 1.7656103e+08 | I5: ='Business Interruption'!I5+'Equipment Failure'!I5+'Workers Compensation'!I14+'Cargo Loss'!I14 -> 1.8635123e+08 | J5: ='Business Interruption'!J5+'Equipment Failure'!J5+'Workers Compensation'!J14+'Cargo Loss'!J14 -> 1.965443e+08 | ... L5: ='Business Interruption'!L5+'Equipment Failure'!L5+'Workers Compensation'!L14+'Cargo Loss'!L14 -> 2.182511e+08 | N5: Interest on Premium and Retained Profit | O5: ='Business Interruption'!C24+'Equipment Failure'!C24+'Workers Compensation'!C23+'Cargo Loss'!C23 -> 1.3183876e+08 | P5: ='Business Interruption'!D24+'Equipment Failure'!D24+'Workers Compensation'!D23+'Cargo Loss'!D23 -> 1.1679868e+08 | Q5: ='Business Interruption'!E24+'Equipment Failure'!E24+'Workers Compensation'!E23+'Cargo Loss'!E23 -> 1.0000488e+08 | R5: ='Business Interruption'!F24+'Equipment Failure'!F24+'Workers Compensation'!F23+'Cargo Loss'!F23 -> 81643262 | S5: ='Business Interruption'!G24+'Equipment Failure'!G24+'Workers Compensation'!G23+'Cargo Loss'!G23 -> 61789783 | T5: ='Business Interruption'!H24+'Equipment Failure'!H24+'Workers Compensation'!H23+'Cargo Loss'!H23 -> 40457607 | U5: ='Business Interruption'!I24+'Equipment Failure'!I24+'Workers Compensation'!I23+'Cargo Loss'!I23 -> 17623740 | V5: ='Business Interruption'!J24+'Equipment Failure'!J24+'Workers Compensation'!J23+'Cargo Loss'!J23 -> -6755959.1 | ... X5: ='Business Interruption'!L24+'Equipment Failure'!L24+'Workers Compensation'!L23+'Cargo Loss'!L23 -> -60388654 | Z5: Interest on Premium and Retained Profit | AA5: ='Business Interruption'!C15+'Equipment Failure'!C15+'Workers Compensation'!C5+'Cargo Loss'!C5 -> 1.3183876e+08 | AB5: ='Business Interruption'!D15+'Equipment Failure'!D15+'Workers Compensation'!D5+'Cargo Loss'!D5 -> 1.6826789e+08 | AC5: ='Business Interruption'!E15+'Equipment Failure'!E15+'Workers Compensation'!E5+'Cargo Loss'!E5 -> 2.0679704e+08 | AD5: ='Business Interruption'!F15+'Equipment Failure'!F15+'Workers Compensation'!F5+'Cargo Loss'!F5 -> 2.4751373e+08 | AE5: ='Business Interruption'!G15+'Equipment Failure'!G15+'Workers Compensation'!G5+'Cargo Loss'!G5 -> 2.9053275e+08 | AF5: ='Business Interruption'!H15+'Equipment Failure'!H15+'Workers Compensation'!H5+'Cargo Loss'!H5 -> 3.3597937e+08 | AG5: ='Business Interruption'!I15+'Equipment Failure'!I15+'Workers Compensation'!I5+'Cargo Loss'!I5 -> 3.8398208e+08 | AH5: ='Business Interruption'!J15+'Equipment Failure'!J15+'Workers Compensation'!J5+'Cargo Loss'!J5 -> 4.3467012e+08 | ... AJ5: ='Business Interruption'!L15+'Equipment Failure'!L15+'Workers Compensation'!L5+'Cargo Loss'!L5 -> 5.4462167e+08
A6: Costs (Inflation + Exposure) | C6: ='Business Interruption'!C6+'Equipment Failure'!C6+'Workers Compensation'!C15+'Cargo Loss'!C15 -> 1.4914014e+10 | D6: ='Business Interruption'!D6+'Equipment Failure'!D6+'Workers Compensation'!D15+'Cargo Loss'!D15 -> 1.5618833e+10 | E6: ='Business Interruption'!E6+'Equipment Failure'!E6+'Workers Compensation'!E15+'Cargo Loss'!E15 -> 1.6352584e+10 | F6: ='Business Interruption'!F6+'Equipment Failure'!F6+'Workers Compensation'!F15+'Cargo Loss'!F15 -> 1.7115128e+10 | G6: ='Business Interruption'!G6+'Equipment Failure'!G6+'Workers Compensation'!G15+'Cargo Loss'!G15 -> 1.7906739e+10 | H6: ='Business Interruption'!H6+'Equipment Failure'!H6+'Workers Compensation'!H15+'Cargo Loss'!H15 -> 1.8727951e+10 | I6: ='Business Interruption'!I6+'Equipment Failure'!I6+'Workers Compensation'!I15+'Cargo Loss'!I15 -> 1.9579477e+10 | J6: ='Business Interruption'!J6+'Equipment Failure'!J6+'Workers Compensation'!J15+'Cargo Loss'!J15 -> 2.0462151e+10 | ... L6: ='Business Interruption'!L6+'Equipment Failure'!L6+'Workers Compensation'!L15+'Cargo Loss'!L15 -> 2.2324687e+10 | N6: Costs (Inflation + Exposure) | O6: ='Business Interruption'!C25+'Equipment Failure'!C25+'Workers Compensation'!C24+'Cargo Loss'!C24 -> 1.7553645e+10 | P6: ='Business Interruption'!D25+'Equipment Failure'!D25+'Workers Compensation'!D24+'Cargo Loss'!D24 -> 1.8383206e+10 | Q6: ='Business Interruption'!E25+'Equipment Failure'!E25+'Workers Compensation'!E24+'Cargo Loss'!E24 -> 1.9246819e+10 | R6: ='Business Interruption'!F25+'Equipment Failure'!F25+'Workers Compensation'!F24+'Cargo Loss'!F24 -> 2.0144321e+10 | S6: ='Business Interruption'!G25+'Equipment Failure'!G25+'Workers Compensation'!G24+'Cargo Loss'!G24 -> 2.1076034e+10 | T6: ='Business Interruption'!H25+'Equipment Failure'!H25+'Workers Compensation'!H24+'Cargo Loss'!H24 -> 2.2042587e+10 | U6: ='Business Interruption'!I25+'Equipment Failure'!I25+'Workers Compensation'!I24+'Cargo Loss'!I24 -> 2.304482e+10 | V6: ='Business Interruption'!J25+'Equipment Failure'!J25+'Workers Compensation'!J24+'Cargo Loss'!J24 -> 2.4083712e+10 | ... X6: ='Business Interruption'!L25+'Equipment Failure'!L25+'Workers Compensation'!L24+'Cargo Loss'!L24 -> 2.6275886e+10 | Z6: Costs (Inflation + Exposure) | AA6: ='Business Interruption'!C16+'Equipment Failure'!C16+'Workers Compensation'!C6+'Cargo Loss'!C6 -> 1.1822196e+10 | AB6: ='Business Interruption'!D16+'Equipment Failure'!D16+'Workers Compensation'!D6+'Cargo Loss'!D6 -> 1.238091e+10 | AC6: ='Business Interruption'!E16+'Equipment Failure'!E16+'Workers Compensation'!E6+'Cargo Loss'!E6 -> 1.2962558e+10 | AD6: ='Business Interruption'!F16+'Equipment Failure'!F16+'Workers Compensation'!F6+'Cargo Loss'!F6 -> 1.3567031e+10 | AE6: ='Business Interruption'!G16+'Equipment Failure'!G16+'Workers Compensation'!G6+'Cargo Loss'!G6 -> 1.4194545e+10 | AF6: ='Business Interruption'!H16+'Equipment Failure'!H16+'Workers Compensation'!H6+'Cargo Loss'!H6 -> 1.4845524e+10 | AG6: ='Business Interruption'!I16+'Equipment Failure'!I16+'Workers Compensation'!I6+'Cargo Loss'!I6 -> 1.5520534e+10 | AH6: ='Business Interruption'!J16+'Equipment Failure'!J16+'Workers Compensation'!J6+'Cargo Loss'!J6 -> 1.6220235e+10 | ... AJ6: ='Business Interruption'!L16+'Equipment Failure'!L16+'Workers Compensation'!L6+'Cargo Loss'!L6 -> 1.7696679e+10
A7: Profit at half year | C7: ='Business Interruption'!C7+'Equipment Failure'!C7+'Workers Compensation'!C16+'Cargo Loss'!C16 -> 1.466854e+08 | D7: ='Business Interruption'!D7+'Equipment Failure'!D7+'Workers Compensation'!D16+'Cargo Loss'!D16 -> 3.0580534e+08 | E7: ='Business Interruption'!E7+'Equipment Failure'!E7+'Workers Compensation'!E16+'Cargo Loss'!E16 -> 4.7840093e+08 | F7: ='Business Interruption'!F7+'Equipment Failure'!F7+'Workers Compensation'!F16+'Cargo Loss'!F16 -> 6.6540125e+08 | G7: ='Business Interruption'!G7+'Equipment Failure'!G7+'Workers Compensation'!G16+'Cargo Loss'!G16 -> 8.6767968e+08 | H7: ='Business Interruption'!H7+'Equipment Failure'!H7+'Workers Compensation'!H16+'Cargo Loss'!H16 -> 1.0860884e+09 | I7: ='Business Interruption'!I7+'Equipment Failure'!I7+'Workers Compensation'!I16+'Cargo Loss'!I16 -> 1.3214798e+09 | J7: ='Business Interruption'!J7+'Equipment Failure'!J7+'Workers Compensation'!J16+'Cargo Loss'!J16 -> 1.5747196e+09 | ... L7: ='Business Interruption'!L7+'Equipment Failure'!L7+'Workers Compensation'!L16+'Cargo Loss'!L16 -> 2.1383236e+09 | N7: Profit at half year | O7: ='Business Interruption'!C26+'Equipment Failure'!C26+'Workers Compensation'!C25+'Cargo Loss'!C25 -> -2.492946e+09 | P7: ='Business Interruption'!D26+'Equipment Failure'!D26+'Workers Compensation'!D25+'Cargo Loss'!D25 -> -5.1452143e+09 | Q7: ='Business Interruption'!E26+'Equipment Failure'!E26+'Workers Compensation'!E25+'Cargo Loss'!E25 -> -7.9645595e+09 | R7: ='Business Interruption'!F26+'Equipment Failure'!F26+'Workers Compensation'!F25+'Cargo Loss'!F25 -> -1.0958651e+10 | S7: ='Business Interruption'!G26+'Equipment Failure'!G26+'Workers Compensation'!G25+'Cargo Loss'!G25 -> -1.4135259e+10 | T7: ='Business Interruption'!H26+'Equipment Failure'!H26+'Workers Compensation'!H25+'Cargo Loss'!H25 -> -1.7502352e+10 | U7: ='Business Interruption'!I26+'Equipment Failure'!I26+'Workers Compensation'!I25+'Cargo Loss'!I25 -> -2.106816e+10 | V7: ='Business Interruption'!J26+'Equipment Failure'!J26+'Workers Compensation'!J25+'Cargo Loss'!J25 -> -2.4841201e+10 | ... X7: ='Business Interruption'!L26+'Equipment Failure'!L26+'Workers Compensation'!L25+'Cargo Loss'!L25 -> -3.3044641e+10 | Z7: Profit at half year | AA7: ='Business Interruption'!C17+'Equipment Failure'!C17+'Workers Compensation'!C7+'Cargo Loss'!C7 -> 3.2385033e+09 | AB7: ='Business Interruption'!D17+'Equipment Failure'!D17+'Workers Compensation'!D7+'Cargo Loss'!D7 -> 6.6906157e+09 | AC7: ='Business Interruption'!E17+'Equipment Failure'!E17+'Workers Compensation'!E7+'Cargo Loss'!E7 -> 1.0367681e+10 | AD7: ='Business Interruption'!F17+'Equipment Failure'!F17+'Workers Compensation'!F7+'Cargo Loss'!F7 -> 1.4280698e+10 | AE7: ='Business Interruption'!G17+'Equipment Failure'!G17+'Workers Compensation'!G7+'Cargo Loss'!G7 -> 1.8440665e+10 | AF7: ='Business Interruption'!H17+'Equipment Failure'!H17+'Workers Compensation'!H7+'Cargo Loss'!H7 -> 2.2858766e+10 | AG7: ='Business Interruption'!I17+'Equipment Failure'!I17+'Workers Compensation'!I7+'Cargo Loss'!I7 -> 2.7546489e+10 | AH7: ='Business Interruption'!J17+'Equipment Failure'!J17+'Workers Compensation'!J7+'Cargo Loss'!J7 -> 3.2515694e+10 | ... AJ7: ='Business Interruption'!L17+'Equipment Failure'!L17+'Workers Compensation'!L7+'Cargo Loss'!L7 -> 4.334808e+10
A8: Interest on Profit | C8: ='Business Interruption'!C8+'Equipment Failure'!C8+'Workers Compensation'!C17+'Cargo Loss'!C17 -> 1295398.4 | D8: ='Business Interruption'!D8+'Equipment Failure'!D8+'Workers Compensation'!D17+'Cargo Loss'!D17 -> 2722135.1 | E8: ='Business Interruption'!E8+'Equipment Failure'!E8+'Workers Compensation'!E17+'Cargo Loss'!E17 -> 4278424.4 | F8: ='Business Interruption'!F8+'Equipment Failure'!F8+'Workers Compensation'!F17+'Cargo Loss'!F17 -> 5967197.7 | G8: ='Business Interruption'!G8+'Equipment Failure'!G8+'Workers Compensation'!G17+'Cargo Loss'!G17 -> 7793844 | H8: ='Business Interruption'!H8+'Equipment Failure'!H8+'Workers Compensation'!H17+'Cargo Loss'!H17 -> 9765046.8 | I8: ='Business Interruption'!I8+'Equipment Failure'!I8+'Workers Compensation'!I17+'Cargo Loss'!I17 -> 11888201 | J8: ='Business Interruption'!J8+'Equipment Failure'!J8+'Workers Compensation'!J17+'Cargo Loss'!J17 -> 14171133 | ... L8: ='Business Interruption'!L8+'Equipment Failure'!L8+'Workers Compensation'!L17+'Cargo Loss'!L17 -> 19249169 | N8: Interest on Profit | O8: ='Business Interruption'!C27+'Equipment Failure'!C27+'Workers Compensation'!C26+'Cargo Loss'!C26 -> -22015539 | P8: ='Business Interruption'!D27+'Equipment Failure'!D27+'Workers Compensation'!D26+'Cargo Loss'!D26 -> -45800273 | Q8: ='Business Interruption'!E27+'Equipment Failure'!E27+'Workers Compensation'!E26+'Cargo Loss'!E26 -> -71228468 | R8: ='Business Interruption'!F27+'Equipment Failure'!F27+'Workers Compensation'!F26+'Cargo Loss'!F26 -> -98275196 | S8: ='Business Interruption'!G27+'Equipment Failure'!G27+'Workers Compensation'!G26+'Cargo Loss'!G26 -> -1.2696851e+08 | T8: ='Business Interruption'!H27+'Equipment Failure'!H27+'Workers Compensation'!H26+'Cargo Loss'!H26 -> -1.5736406e+08 | U8: ='Business Interruption'!I27+'Equipment Failure'!I27+'Workers Compensation'!I26+'Cargo Loss'!I26 -> -1.8953185e+08 | V8: ='Business Interruption'!J27+'Equipment Failure'!J27+'Workers Compensation'!J26+'Cargo Loss'!J26 -> -2.2354961e+08 | ... X8: ='Business Interruption'!L27+'Equipment Failure'!L27+'Workers Compensation'!L26+'Cargo Loss'!L26 -> -2.9746755e+08 | Z8: Interest on Profit | AA8: ='Business Interruption'!C18+'Equipment Failure'!C18+'Workers Compensation'!C8+'Cargo Loss'!C8 -> 28599655 | AB8: ='Business Interruption'!D18+'Equipment Failure'!D18+'Workers Compensation'!D8+'Cargo Loss'!D8 -> 59556709 | AC8: ='Business Interruption'!E18+'Equipment Failure'!E18+'Workers Compensation'!E8+'Cargo Loss'!E8 -> 92720006 | AD8: ='Business Interruption'!F18+'Equipment Failure'!F18+'Workers Compensation'!F8+'Cargo Loss'!F8 -> 1.2806671e+08 | AE8: ='Business Interruption'!G18+'Equipment Failure'!G18+'Workers Compensation'!G8+'Cargo Loss'!G8 -> 1.6564139e+08 | AF8: ='Business Interruption'!H18+'Equipment Failure'!H18+'Workers Compensation'!H8+'Cargo Loss'!H8 -> 2.0552371e+08 | AG8: ='Business Interruption'!I18+'Equipment Failure'!I18+'Workers Compensation'!I8+'Cargo Loss'!I8 -> 2.4781173e+08 | AH8: ='Business Interruption'!J18+'Equipment Failure'!J18+'Workers Compensation'!J8+'Cargo Loss'!J8 -> 2.926135e+08 | ... AJ8: ='Business Interruption'!L18+'Equipment Failure'!L18+'Workers Compensation'!L8+'Cargo Loss'!L8 -> 3.9021901e+08
A9: Final Profit | C9: ='Business Interruption'!C9+'Equipment Failure'!C9+'Workers Compensation'!C18+'Cargo Loss'!C18 -> 1.479808e+08 | D9: ='Business Interruption'!D9+'Equipment Failure'!D9+'Workers Compensation'!D18+'Cargo Loss'!D18 -> 3.0852748e+08 | E9: ='Business Interruption'!E9+'Equipment Failure'!E9+'Workers Compensation'!E18+'Cargo Loss'!E18 -> 4.8267936e+08 | F9: ='Business Interruption'!F9+'Equipment Failure'!F9+'Workers Compensation'!F18+'Cargo Loss'!F18 -> 6.7136845e+08 | G9: ='Business Interruption'!G9+'Equipment Failure'!G9+'Workers Compensation'!G18+'Cargo Loss'!G18 -> 8.7547352e+08 | H9: ='Business Interruption'!H9+'Equipment Failure'!H9+'Workers Compensation'!H18+'Cargo Loss'!H18 -> 1.0958535e+09 | I9: ='Business Interruption'!I9+'Equipment Failure'!I9+'Workers Compensation'!I18+'Cargo Loss'!I18 -> 1.333368e+09 | J9: ='Business Interruption'!J9+'Equipment Failure'!J9+'Workers Compensation'!J18+'Cargo Loss'!J18 -> 1.5888907e+09 | ... L9: ='Business Interruption'!L9+'Equipment Failure'!L9+'Workers Compensation'!L18+'Cargo Loss'!L18 -> 2.1575728e+09 | N9: Final Profit | O9: ='Business Interruption'!C28+'Equipment Failure'!C28+'Workers Compensation'!C27+'Cargo Loss'!C27 -> -2.5149615e+09 | P9: ='Business Interruption'!D28+'Equipment Failure'!D28+'Workers Compensation'!D27+'Cargo Loss'!D27 -> -5.1910145e+09 | Q9: ='Business Interruption'!E28+'Equipment Failure'!E28+'Workers Compensation'!E27+'Cargo Loss'!E27 -> -8.035788e+09 | R9: ='Business Interruption'!F28+'Equipment Failure'!F28+'Workers Compensation'!F27+'Cargo Loss'!F27 -> -1.1056926e+10 | S9: ='Business Interruption'!G28+'Equipment Failure'!G28+'Workers Compensation'!G27+'Cargo Loss'!G27 -> -1.4262227e+10 | T9: ='Business Interruption'!H28+'Equipment Failure'!H28+'Workers Compensation'!H27+'Cargo Loss'!H27 -> -1.7659716e+10 | U9: ='Business Interruption'!I28+'Equipment Failure'!I28+'Workers Compensation'!I27+'Cargo Loss'!I27 -> -2.1257691e+10 | V9: ='Business Interruption'!J28+'Equipment Failure'!J28+'Workers Compensation'!J27+'Cargo Loss'!J27 -> -2.5064751e+10 | ... X9: ='Business Interruption'!L28+'Equipment Failure'!L28+'Workers Compensation'!L27+'Cargo Loss'!L27 -> -3.3342109e+10 | Z9: Final Profit | AA9: ='Business Interruption'!C19+'Equipment Failure'!C19+'Workers Compensation'!C9+'Cargo Loss'!C9 -> 3.2671029e+09 | AB9: ='Business Interruption'!D19+'Equipment Failure'!D19+'Workers Compensation'!D9+'Cargo Loss'!D9 -> 6.7501725e+09 | AC9: ='Business Interruption'!E19+'Equipment Failure'!E19+'Workers Compensation'!E9+'Cargo Loss'!E9 -> 1.0460401e+10 | AD9: ='Business Interruption'!F19+'Equipment Failure'!F19+'Workers Compensation'!F9+'Cargo Loss'!F9 -> 1.4408765e+10 | AE9: ='Business Interruption'!G19+'Equipment Failure'!G19+'Workers Compensation'!G9+'Cargo Loss'!G9 -> 1.8606306e+10 | AF9: ='Business Interruption'!H19+'Equipment Failure'!H19+'Workers Compensation'!H9+'Cargo Loss'!H9 -> 2.306429e+10 | AG9: ='Business Interruption'!I19+'Equipment Failure'!I19+'Workers Compensation'!I9+'Cargo Loss'!I9 -> 2.7794301e+10 | AH9: ='Business Interruption'!J19+'Equipment Failure'!J19+'Workers Compensation'!J9+'Cargo Loss'!J9 -> 3.2808308e+10 | ... AJ9: ='Business Interruption'!L19+'Equipment Failure'!L19+'Workers Compensation'!L9+'Cargo Loss'!L9 -> 4.3738299e+10

Sheet Business Interruption
A1: Business Interruption
B2: Expected Costs | C2: 1 | D2: 2 | E2: 3 | F2: 4 | G2: 5 | H2: 6 | I2: 7 | J2: 8 | K2: 9 | L2: 10
B3: Retained Earnings | C3: 0 | D3: =C9 -> 167518.29 | E3: =D9 -> 345726.93 | F3: =E9 -> 535307.22 | G3: =F9 -> 736886.61 | H3: =G9 -> 951069.19 | I3: =H9 -> 1178454 | J3: =I9 -> 1419646.1 | K3: =J9 -> 1675263.6 | L3: =K9 -> 1945941.9
B4: Premium Revenue (Inflation + Exposure) | C4: 6290203 | D4: =$C4*_xlfn.XLOOKUP(D2,'Interest, etc. BI and EF'!$A$2:$A$11,'Interest, etc. BI and EF'!$I$2:$I$11) -> 6592754.9 | E4: =$C4*_xlfn.XLOOKUP(E2,'Interest, etc. BI and EF'!$A$2:$A$11,'Interest, etc. BI and EF'!$I$2:$I$11) -> 6908094.8 | F4: =$C4*_xlfn.XLOOKUP(F2,'Interest, etc. BI and EF'!$A$2:$A$11,'Interest, etc. BI and EF'!$I$2:$I$11) -> 7236069.3 | G4: =$C4*_xlfn.XLOOKUP(G2,'Interest, etc. BI and EF'!$A$2:$A$11,'Interest, etc. BI and EF'!$I$2:$I$11) -> 7576738.5 | H4: =$C4*_xlfn.XLOOKUP(H2,'Interest, etc. BI and EF'!$A$2:$A$11,'Interest, etc. BI and EF'!$I$2:$I$11) -> 7930299.3 | I4: =$C4*_xlfn.XLOOKUP(I2,'Interest, etc. BI and EF'!$A$2:$A$11,'Interest, etc. BI and EF'!$I$2:$I$11) -> 8297038.8 | J4: =$C4*_xlfn.XLOOKUP(J2,'Interest, etc. BI and EF'!$A$2:$A$11,'Interest, etc. BI and EF'!$I$2:$I$11) -> 8677305.3 | K4: =$C4*_xlfn.XLOOKUP(K2,'Interest, etc. BI and EF'!$A$2:$A$11,'Interest, etc. BI and EF'!$I$2:$I$11) -> 9071490.3 | L4: =$C4*_xlfn.XLOOKUP(L2,'Interest, etc. BI and EF'!$A$2:$A$11,'Interest, etc. BI and EF'!$I$2:$I$11) -> 9480017.5
A5: half of current year | B5: Interest on Premium and Retained Profits | C5: =(C3+C4)*((1+_xlfn.XLOOKUP(C$2,'Interest, etc. BI and EF'!$A$2:$A$11,'Interest, etc. BI and EF'!$C$2:$C$11))^(1/2)-1) -> 55549.623 | D5: =(D3+D4)*((1+_xlfn.XLOOKUP(D$2,'Interest, etc. BI and EF'!$A$2:$A$11,'Interest, etc. BI and EF'!$C$2:$C$11))^(1/2)-1) -> 60176.768 | E5: =(E3+E4)*((1+_xlfn.XLOOKUP(E$2,'Interest, etc. BI and EF'!$A$2:$A$11,'Interest, etc. BI and EF'!$C$2:$C$11))^(1/2)-1) -> 64872.213 | F5: =(F3+F4)*((1+_xlfn.XLOOKUP(F$2,'Interest, etc. BI and EF'!$A$2:$A$11,'Interest, etc. BI and EF'!$C$2:$C$11))^(1/2)-1) -> 69692.295 | G5: =(G3+G4)*((1+_xlfn.XLOOKUP(G$2,'Interest, etc. BI and EF'!$A$2:$A$11,'Interest, etc. BI and EF'!$C$2:$C$11))^(1/2)-1) -> 74676.287 | H5: =(H3+H4)*((1+_xlfn.XLOOKUP(H$2,'Interest, etc. BI and EF'!$A$2:$A$11,'Interest, etc. BI and EF'!$C$2:$C$11))^(1/2)-1) -> 79852.595 | I5: =(I3+I4)*((1+_xlfn.XLOOKUP(I$2,'Interest, etc. BI and EF'!$A$2:$A$11,'Interest, etc. BI and EF'!$C$2:$C$11))^(1/2)-1) -> 85242.74 | J5: =(J3+J4)*((1+_xlfn.XLOOKUP(J$2,'Interest, etc. BI and EF'!$A$2:$A$11,'Interest, etc. BI and EF'!$C$2:$C$11))^(1/2)-1) -> 90863.947 | ... L5: =(L3+L4)*((1+_xlfn.XLOOKUP(L$2,'Interest, etc. BI and EF'!$A$2:$A$11,'Interest, etc. BI and EF'!$C$2:$C$11))^(1/2)-1) -> 102856.38
A6: half previous year + half current year | B6: Costs (Inflation + Exposure) | C6: =6105802*_xlfn.XLOOKUP(C12,'Interest, etc. BI and EF'!$A$2:$A$11,'Interest, etc. BI and EF'!$L$2:$L$11) -> 6179700.8 | D6: =$C6*_xlfn.XLOOKUP(D2,'Interest, etc. BI and EF'!$A$2:$A$11,'Interest, etc. BI and EF'!$L$2:$L$11)/_xlfn.XLOOKUP($C2,'Interest, etc. BI and EF'!$A$2:$A$11,'Interest, etc. BI and EF'!$L$2:$L$11) -> 6477773.4 | E6: =$C6*_xlfn.XLOOKUP(E2,'Interest, etc. BI and EF'!$A$2:$A$11,'Interest, etc. BI and EF'!$L$2:$L$11)/_xlfn.XLOOKUP($C2,'Interest, etc. BI and EF'!$A$2:$A$11,'Interest, etc. BI and EF'!$L$2:$L$11) -> 6788131.6 | F6: =$C6*_xlfn.XLOOKUP(F2,'Interest, etc. BI and EF'!$A$2:$A$11,'Interest, etc. BI and EF'!$L$2:$L$11)/_xlfn.XLOOKUP($C2,'Interest, etc. BI and EF'!$A$2:$A$11,'Interest, etc. BI and EF'!$L$2:$L$11) -> 7110731.7 | G6: =$C6*_xlfn.XLOOKUP(G2,'Interest, etc. BI and EF'!$A$2:$A$11,'Interest, etc. BI and EF'!$L$2:$L$11)/_xlfn.XLOOKUP($C2,'Interest, etc. BI and EF'!$A$2:$A$11,'Interest, etc. BI and EF'!$L$2:$L$11) -> 7445699 | H6: =$C6*_xlfn.XLOOKUP(H2,'Interest, etc. BI and EF'!$A$2:$A$11,'Interest, etc. BI and EF'!$L$2:$L$11)/_xlfn.XLOOKUP($C2,'Interest, etc. BI and EF'!$A$2:$A$11,'Interest, etc. BI and EF'!$L$2:$L$11) -> 7793268.1 | I6: =$C6*_xlfn.XLOOKUP(I2,'Interest, etc. BI and EF'!$A$2:$A$11,'Interest, etc. BI and EF'!$L$2:$L$11)/_xlfn.XLOOKUP($C2,'Interest, etc. BI and EF'!$A$2:$A$11,'Interest, etc. BI and EF'!$L$2:$L$11) -> 8153746.9 | J6: =$C6*_xlfn.XLOOKUP(J2,'Interest, etc. BI and EF'!$A$2:$A$11,'Interest, etc. BI and EF'!$L$2:$L$11)/_xlfn.XLOOKUP($C2,'Interest, etc. BI and EF'!$A$2:$A$11,'Interest, etc. BI and EF'!$L$2:$L$11) -> 8527493.3 | K6: =$C6*_xlfn.XLOOKUP(K2,'Interest, etc. BI and EF'!$A$2:$A$11,'Interest, etc. BI and EF'!$L$2:$L$11)/_xlfn.XLOOKUP($C2,'Interest, etc. BI and EF'!$A$2:$A$11,'Interest, etc. BI and EF'!$L$2:$L$11) -> 8914901.9 | L6: =$C6*_xlfn.XLOOKUP(L2,'Interest, etc. BI and EF'!$A$2:$A$11,'Interest, etc. BI and EF'!$L$2:$L$11)/_xlfn.XLOOKUP($C2,'Interest, etc. BI and EF'!$A$2:$A$11,'Interest, etc. BI and EF'!$L$2:$L$11) -> 9316395.3
B7: Profit at half year | C7: =C3+C4+C5-C6 -> 166051.86 | D7: =D3+D4+D5-D6 -> 342676.59 | E7: =E3+E4+E5-E6 -> 530562.31 | F7: =F3+F4+F5-F6 -> 730337.08 | G7: =G3+G4+G5-G6 -> 942602.36 | H7: =H3+H4+H5-H6 -> 1167952.9 | I7: =I3+I4+I5-I6 -> 1406988.7 | J7: =J3+J4+J5-J6 -> 1660322.1 | ... L7: =L3+L4+L5-L6 -> 2212420.4
B8: Interest on Profit | C8: =C7*((1+_xlfn.XLOOKUP(C$2,'Interest, etc. BI and EF'!$A$2:$A$11,'Interest, etc. BI and EF'!$C$2:$C$11))^(1/2)-1) -> 1466.4262 | D8: =D7*((1+_xlfn.XLOOKUP(D$2,'Interest, etc. BI and EF'!$A$2:$A$11,'Interest, etc. BI and EF'!$C$2:$C$11))^(1/2)-1) -> 3050.3456 | E8: =E7*((1+_xlfn.XLOOKUP(E$2,'Interest, etc. BI and EF'!$A$2:$A$11,'Interest, etc. BI and EF'!$C$2:$C$11))^(1/2)-1) -> 4744.9128 | F8: =F7*((1+_xlfn.XLOOKUP(F$2,'Interest, etc. BI and EF'!$A$2:$A$11,'Interest, etc. BI and EF'!$C$2:$C$11))^(1/2)-1) -> 6549.5304 | G8: =G7*((1+_xlfn.XLOOKUP(G$2,'Interest, etc. BI and EF'!$A$2:$A$11,'Interest, etc. BI and EF'!$C$2:$C$11))^(1/2)-1) -> 8466.8294 | H8: =H7*((1+_xlfn.XLOOKUP(H$2,'Interest, etc. BI and EF'!$A$2:$A$11,'Interest, etc. BI and EF'!$C$2:$C$11))^(1/2)-1) -> 10501.092 | I8: =I7*((1+_xlfn.XLOOKUP(I$2,'Interest, etc. BI and EF'!$A$2:$A$11,'Interest, etc. BI and EF'!$C$2:$C$11))^(1/2)-1) -> 12657.449 | J8: =J7*((1+_xlfn.XLOOKUP(J$2,'Interest, etc. BI and EF'!$A$2:$A$11,'Interest, etc. BI and EF'!$C$2:$C$11))^(1/2)-1) -> 14941.482 | ... L8: =L7*((1+_xlfn.XLOOKUP(L$2,'Interest, etc. BI and EF'!$A$2:$A$11,'Interest, etc. BI and EF'!$C$2:$C$11))^(1/2)-1) -> 19916.188
B9: Final Profit | C9: =C7+C8 -> 167518.29 | D9: =D7+D8 -> 345726.93 | E9: =E7+E8 -> 535307.22 | F9: =F7+F8 -> 736886.61 | G9: =G7+G8 -> 951069.19 | H9: =H7+H8 -> 1178454 | I9: =I7+I8 -> 1419646.1 | J9: =J7+J8 -> 1675263.6 | ... L9: =L7+L8 -> 2232336.6
B12: Lower Bound | C12: 1 | D12: 2 | E12: 3 | F12: 4 | G12: 5 | H12: 6 | I12: 7 | J12: 8 | K12: 9 | L12: 10
B13: Retained Earnings | C13: 0 | D13: =C19 -> 6273116 | E13: =D19 -> 12961049 | F13: =E19 -> 20084758 | G13: =F19 -> 27664958 | H13: =G19 -> 35722588 | I13: =H19 -> 44279084 | J13: =I19 -> 53356532 | K13: =J19 -> 62977771 | L13: =K19 -> 73166457
B14: Premium Revenue (Inflation + Exposure) | C14: 6290203 | D14: =$C14*_xlfn.XLOOKUP(D12,'Interest, etc. BI and EF'!$A$2:$A$11,'Interest, etc. BI and EF'!$I$2:$I$11) -> 6592754.9 | E14: =$C14*_xlfn.XLOOKUP(E12,'Interest, etc. BI and EF'!$A$2:$A$11,'Interest, etc. BI and EF'!$I$2:$I$11) -> 6908094.8 | F14: =$C14*_xlfn.XLOOKUP(F12,'Interest, etc. BI and EF'!$A$2:$A$11,'Interest, etc. BI and EF'!$I$2:$I$11) -> 7236069.3 | G14: =$C14*_xlfn.XLOOKUP(G12,'Interest, etc. BI and EF'!$A$2:$A$11,'Interest, etc. BI and EF'!$I$2:$I$11) -> 7576738.5 | H14: =$C14*_xlfn.XLOOKUP(H12,'Interest, etc. BI and EF'!$A$2:$A$11,'Interest, etc. BI and EF'!$I$2:$I$11) -> 7930299.3 | I14: =$C14*_xlfn.XLOOKUP(I12,'Interest, etc. BI and EF'!$A$2:$A$11,'Interest, etc. BI and EF'!$I$2:$I$11) -> 8297038.8 | J14: =$C14*_xlfn.XLOOKUP(J12,'Interest, etc. BI and EF'!$A$2:$A$11,'Interest, etc. BI and EF'!$I$2:$I$11) -> 8677305.3 | K14: =$C14*_xlfn.XLOOKUP(K12,'Interest, etc. BI and EF'!$A$2:$A$11,'Interest, etc. BI and EF'!$I$2:$I$11) -> 9071490.3 | L14: =$C14*_xlfn.XLOOKUP(L12,'Interest, etc. BI and EF'!$A$2:$A$11,'Interest, etc. BI and EF'!$I$2:$I$11) -> 9480017.5
A15: half of current year | B15: Interest on Premium and Retained Profits | C15: =(C13+C14)*((1+_xlfn.XLOOKUP(C$12,'Interest, etc. BI and EF'!$A$2:$A$11,'Interest, etc. BI and EF'!$C$2:$C$11))^(1/2)-1) -> 55549.623 | D15: =(D13+D14)*((1+_xlfn.XLOOKUP(D$12,'Interest, etc. BI and EF'!$A$2:$A$11,'Interest, etc. BI and EF'!$C$2:$C$11))^(1/2)-1) -> 114525.92 | E15: =(E13+E14)*((1+_xlfn.XLOOKUP(E$12,'Interest, etc. BI and EF'!$A$2:$A$11,'Interest, etc. BI and EF'!$C$2:$C$11))^(1/2)-1) -> 177693.28 | F15: =(F13+F14)*((1+_xlfn.XLOOKUP(F$12,'Interest, etc. BI and EF'!$A$2:$A$11,'Interest, etc. BI and EF'!$C$2:$C$11))^(1/2)-1) -> 245008.23 | G15: =(G13+G14)*((1+_xlfn.XLOOKUP(G$12,'Interest, etc. BI and EF'!$A$2:$A$11,'Interest, etc. BI and EF'!$C$2:$C$11))^(1/2)-1) -> 316554.94 | H15: =(H13+H14)*((1+_xlfn.XLOOKUP(H$12,'Interest, etc. BI and EF'!$A$2:$A$11,'Interest, etc. BI and EF'!$C$2:$C$11))^(1/2)-1) -> 392484.15 | I15: =(I13+I14)*((1+_xlfn.XLOOKUP(I$12,'Interest, etc. BI and EF'!$A$2:$A$11,'Interest, etc. BI and EF'!$C$2:$C$11))^(1/2)-1) -> 472981.49 | J15: =(J13+J14)*((1+_xlfn.XLOOKUP(J$12,'Interest, etc. BI and EF'!$A$2:$A$11,'Interest, etc. BI and EF'!$C$2:$C$11))^(1/2)-1) -> 558251.6 | ... L15: =(L13+L14)*((1+_xlfn.XLOOKUP(L$12,'Interest, etc. BI and EF'!$A$2:$A$11,'Interest, etc. BI and EF'!$C$2:$C$11))^(1/2)-1) -> 743982.79
A16: previous years + half of current year | B16: Costs (Inflation + Exposure) | C16: =126025.1*_xlfn.XLOOKUP(C12,'Interest, etc. BI and EF'!$A$2:$A$11,'Interest, etc. BI and EF'!$L$2:$L$11) -> 127550.39 | D16: =$C16*_xlfn.XLOOKUP(D12,'Interest, etc. BI and EF'!$A$2:$A$11,'Interest, etc. BI and EF'!$L$2:$L$11)/_xlfn.XLOOKUP($C12,'Interest, etc. BI and EF'!$A$2:$A$11,'Interest, etc. BI and EF'!$L$2:$L$11) -> 133702.67 | E16: =$C16*_xlfn.XLOOKUP(E12,'Interest, etc. BI and EF'!$A$2:$A$11,'Interest, etc. BI and EF'!$L$2:$L$11)/_xlfn.XLOOKUP($C12,'Interest, etc. BI and EF'!$A$2:$A$11,'Interest, etc. BI and EF'!$L$2:$L$11) -> 140108.53 | F16: =$C16*_xlfn.XLOOKUP(F12,'Interest, etc. BI and EF'!$A$2:$A$11,'Interest, etc. BI and EF'!$L$2:$L$11)/_xlfn.XLOOKUP($C12,'Interest, etc. BI and EF'!$A$2:$A$11,'Interest, etc. BI and EF'!$L$2:$L$11) -> 146767.07 | G16: =$C16*_xlfn.XLOOKUP(G12,'Interest, etc. BI and EF'!$A$2:$A$11,'Interest, etc. BI and EF'!$L$2:$L$11)/_xlfn.XLOOKUP($C12,'Interest, etc. BI and EF'!$A$2:$A$11,'Interest, etc. BI and EF'!$L$2:$L$11) -> 153680.87 | H16: =$C16*_xlfn.XLOOKUP(H12,'Interest, etc. BI and EF'!$A$2:$A$11,'Interest, etc. BI and EF'!$L$2:$L$11)/_xlfn.XLOOKUP($C12,'Interest, etc. BI and EF'!$A$2:$A$11,'Interest, etc. BI and EF'!$L$2:$L$11) -> 160854.77 | I16: =$C16*_xlfn.XLOOKUP(I12,'Interest, etc. BI and EF'!$A$2:$A$11,'Interest, etc. BI and EF'!$L$2:$L$11)/_xlfn.XLOOKUP($C12,'Interest, etc. BI and EF'!$A$2:$A$11,'Interest, etc. BI and EF'!$L$2:$L$11) -> 168295.13 | J16: =$C16*_xlfn.XLOOKUP(J12,'Interest, etc. BI and EF'!$A$2:$A$11,'Interest, etc. BI and EF'!$L$2:$L$11)/_xlfn.XLOOKUP($C12,'Interest, etc. BI and EF'!$A$2:$A$11,'Interest, etc. BI and EF'!$L$2:$L$11) -> 176009.34 | K16: =$C16*_xlfn.XLOOKUP(K12,'Interest, etc. BI and EF'!$A$2:$A$11,'Interest, etc. BI and EF'!$L$2:$L$11)/_xlfn.XLOOKUP($C12,'Interest, etc. BI and EF'!$A$2:$A$11,'Interest, etc. BI and EF'!$L$2:$L$11) -> 184005.54 | L16: =$C16*_xlfn.XLOOKUP(L12,'Interest, etc. BI and EF'!$A$2:$A$11,'Interest, etc. BI and EF'!$L$2:$L$11)/_xlfn.XLOOKUP($C12,'Interest, etc. BI and EF'!$A$2:$A$11,'Interest, etc. BI and EF'!$L$2:$L$11) -> 192292.45
B17: Profit at half year | C17: =C13+C14+C15-C16 -> 6218202.2 | D17: =D13+D14+D15-D16 -> 12846694 | E17: =E13+E14+E15-E16 -> 19906729 | F17: =F13+F14+F15-F16 -> 27419069 | G17: =G13+G14+G15-G16 -> 35404571 | H17: =H13+H14+H15-H16 -> 43884517 | I17: =I13+I14+I15-I16 -> 52880809 | J17: =J13+J14+J15-J16 -> 62416079 | ... L17: =L13+L14+L15-L16 -> 83198165
B18: Interest on Profit | C18: =C17*((1+_xlfn.XLOOKUP(C$12,'Interest, etc. BI and EF'!$A$2:$A$11,'Interest, etc. BI and EF'!$C$2:$C$11))^(1/2)-1) -> 54913.774 | D18: =D17*((1+_xlfn.XLOOKUP(D$12,'Interest, etc. BI and EF'!$A$2:$A$11,'Interest, etc. BI and EF'!$C$2:$C$11))^(1/2)-1) -> 114355.22 | E18: =E17*((1+_xlfn.XLOOKUP(E$12,'Interest, etc. BI and EF'!$A$2:$A$11,'Interest, etc. BI and EF'!$C$2:$C$11))^(1/2)-1) -> 178029.41 | F18: =F17*((1+_xlfn.XLOOKUP(F$12,'Interest, etc. BI and EF'!$A$2:$A$11,'Interest, etc. BI and EF'!$C$2:$C$11))^(1/2)-1) -> 245889.24 | G18: =G17*((1+_xlfn.XLOOKUP(G$12,'Interest, etc. BI and EF'!$A$2:$A$11,'Interest, etc. BI and EF'!$C$2:$C$11))^(1/2)-1) -> 318017.94 | H18: =H17*((1+_xlfn.XLOOKUP(H$12,'Interest, etc. BI and EF'!$A$2:$A$11,'Interest, etc. BI and EF'!$C$2:$C$11))^(1/2)-1) -> 394566.74 | I18: =I17*((1+_xlfn.XLOOKUP(I$12,'Interest, etc. BI and EF'!$A$2:$A$11,'Interest, etc. BI and EF'!$C$2:$C$11))^(1/2)-1) -> 475722.49 | J18: =J17*((1+_xlfn.XLOOKUP(J$12,'Interest, etc. BI and EF'!$A$2:$A$11,'Interest, etc. BI and EF'!$C$2:$C$11))^(1/2)-1) -> 561691.45 | ... L18: =L17*((1+_xlfn.XLOOKUP(L$12,'Interest, etc. BI and EF'!$A$2:$A$11,'Interest, etc. BI and EF'!$C$2:$C$11))^(1/2)-1) -> 748949.1
B19: Final Profit | C19: =C17+C18 -> 6273116 | D19: =D17+D18 -> 12961049 | E19: =E17+E18 -> 20084758 | F19: =F17+F18 -> 27664958 | G19: =G17+G18 -> 35722588 | H19: =H17+H18 -> 44279084 | I19: =I17+I18 -> 53356532 | J19: =J17+J18 -> 62977771 | ... L19: =L17+L18 -> 83947114
B21: Upper Bound | C21: 1 | D21: 2 | E21: 3 | F21: 4 | G21: 5 | H21: 6 | I21: 7 | J21: 8 | K21: 9 | L21: 10
B22: Retained Earnings | C22: 0 | D22: =C28 -> -8502911.2 | E22: =D28 -> -17569024 | F22: =E28 -> -27226453 | G22: =F28 -> -37503095 | H22: =G28 -> -48427226 | I22: =H28 -> -60027834 | J22: =I28 -> -72334820 | K22: =J28 -> -85379123 | L22: =K28 -> -99192798
B23: Premium Revenue (Inflation + Exposure) | C23: 6290203 | D23: =$C23*_xlfn.XLOOKUP(D21,'Interest, etc. BI and EF'!$A$2:$A$11,'Interest, etc. BI and EF'!$I$2:$I$11) -> 6592754.9 | E23: =$C23*_xlfn.XLOOKUP(E21,'Interest, etc. BI and EF'!$A$2:$A$11,'Interest, etc. BI and EF'!$I$2:$I$11) -> 6908094.8 | F23: =$C23*_xlfn.XLOOKUP(F21,'Interest, etc. BI and EF'!$A$2:$A$11,'Interest, etc. BI and EF'!$I$2:$I$11) -> 7236069.3 | G23: =$C23*_xlfn.XLOOKUP(G21,'Interest, etc. BI and EF'!$A$2:$A$11,'Interest, etc. BI and EF'!$I$2:$I$11) -> 7576738.5 | H23: =$C23*_xlfn.XLOOKUP(H21,'Interest, etc. BI and EF'!$A$2:$A$11,'Interest, etc. BI and EF'!$I$2:$I$11) -> 7930299.3 | I23: =$C23*_xlfn.XLOOKUP(I21,'Interest, etc. BI and EF'!$A$2:$A$11,'Interest, etc. BI and EF'!$I$2:$I$11) -> 8297038.8 | J23: =$C23*_xlfn.XLOOKUP(J21,'Interest, etc. BI and EF'!$A$2:$A$11,'Interest, etc. BI and EF'!$I$2:$I$11) -> 8677305.3 | K23: =$C23*_xlfn.XLOOKUP(K21,'Interest, etc. BI and EF'!$A$2:$A$11,'Interest, etc. BI and EF'!$I$2:$I$11) -> 9071490.3 | L23: =$C23*_xlfn.XLOOKUP(L21,'Interest, etc. BI and EF'!$A$2:$A$11,'Interest, etc. BI and EF'!$I$2:$I$11) -> 9480017.5
B24: Interest on Premium and Retained Profits | C24: =(C22+C23)*((1+_xlfn.XLOOKUP(C$21,'Interest, etc. BI and EF'!$A$2:$A$11,'Interest, etc. BI and EF'!$C$2:$C$11))^(1/2)-1) -> 55549.623 | D24: =(D22+D23)*((1+_xlfn.XLOOKUP(D$21,'Interest, etc. BI and EF'!$A$2:$A$11,'Interest, etc. BI and EF'!$C$2:$C$11))^(1/2)-1) -> -17003.311 | E24: =(E22+E23)*((1+_xlfn.XLOOKUP(E$21,'Interest, etc. BI and EF'!$A$2:$A$11,'Interest, etc. BI and EF'!$C$2:$C$11))^(1/2)-1) -> -95342.582 | F24: =(F22+F23)*((1+_xlfn.XLOOKUP(F$21,'Interest, etc. BI and EF'!$A$2:$A$11,'Interest, etc. BI and EF'!$C$2:$C$11))^(1/2)-1) -> -179270.13 | G24: =(G22+G23)*((1+_xlfn.XLOOKUP(G$21,'Interest, etc. BI and EF'!$A$2:$A$11,'Interest, etc. BI and EF'!$C$2:$C$11))^(1/2)-1) -> -268810.44 | H24: =(H22+H23)*((1+_xlfn.XLOOKUP(H$21,'Interest, etc. BI and EF'!$A$2:$A$11,'Interest, etc. BI and EF'!$C$2:$C$11))^(1/2)-1) -> -364108.83 | I24: =(I22+I23)*((1+_xlfn.XLOOKUP(I$21,'Interest, etc. BI and EF'!$A$2:$A$11,'Interest, etc. BI and EF'!$C$2:$C$11))^(1/2)-1) -> -465376.82 | J24: =(J22+J23)*((1+_xlfn.XLOOKUP(J$21,'Interest, etc. BI and EF'!$A$2:$A$11,'Interest, etc. BI and EF'!$C$2:$C$11))^(1/2)-1) -> -572863.31 | ... L24: =(L22+L23)*((1+_xlfn.XLOOKUP(L$21,'Interest, etc. BI and EF'!$A$2:$A$11,'Interest, etc. BI and EF'!$C$2:$C$11))^(1/2)-1) -> -807593.6
B25: Costs (Inflation + Exposure) | C25: =14597556*_xlfn.XLOOKUP(C21,'Interest, etc. BI and EF'!$A$2:$A$11,'Interest, etc. BI and EF'!$L$2:$L$11) -> 14774231 | D25: =$C25*_xlfn.XLOOKUP(D21,'Interest, etc. BI and EF'!$A$2:$A$11,'Interest, etc. BI and EF'!$L$2:$L$11)/_xlfn.XLOOKUP($C21,'Interest, etc. BI and EF'!$A$2:$A$11,'Interest, etc. BI and EF'!$L$2:$L$11) -> 15486853 | E25: =$C25*_xlfn.XLOOKUP(E21,'Interest, etc. BI and EF'!$A$2:$A$11,'Interest, etc. BI and EF'!$L$2:$L$11)/_xlfn.XLOOKUP($C21,'Interest, etc. BI and EF'!$A$2:$A$11,'Interest, etc. BI and EF'!$L$2:$L$11) -> 16228848 | F25: =$C25*_xlfn.XLOOKUP(F21,'Interest, etc. BI and EF'!$A$2:$A$11,'Interest, etc. BI and EF'!$L$2:$L$11)/_xlfn.XLOOKUP($C21,'Interest, etc. BI and EF'!$A$2:$A$11,'Interest, etc. BI and EF'!$L$2:$L$11) -> 17000110 | G25: =$C25*_xlfn.XLOOKUP(G21,'Interest, etc. BI and EF'!$A$2:$A$11,'Interest, etc. BI and EF'!$L$2:$L$11)/_xlfn.XLOOKUP($C21,'Interest, etc. BI and EF'!$A$2:$A$11,'Interest, etc. BI and EF'!$L$2:$L$11) -> 17800939 | H25: =$C25*_xlfn.XLOOKUP(H21,'Interest, etc. BI and EF'!$A$2:$A$11,'Interest, etc. BI and EF'!$L$2:$L$11)/_xlfn.XLOOKUP($C21,'Interest, etc. BI and EF'!$A$2:$A$11,'Interest, etc. BI and EF'!$L$2:$L$11) -> 18631896 | I25: =$C25*_xlfn.XLOOKUP(I21,'Interest, etc. BI and EF'!$A$2:$A$11,'Interest, etc. BI and EF'!$L$2:$L$11)/_xlfn.XLOOKUP($C21,'Interest, etc. BI and EF'!$A$2:$A$11,'Interest, etc. BI and EF'!$L$2:$L$11) -> 19493717 | J25: =$C25*_xlfn.XLOOKUP(J21,'Interest, etc. BI and EF'!$A$2:$A$11,'Interest, etc. BI and EF'!$L$2:$L$11)/_xlfn.XLOOKUP($C21,'Interest, etc. BI and EF'!$A$2:$A$11,'Interest, etc. BI and EF'!$L$2:$L$11) -> 20387258 | K25: =$C25*_xlfn.XLOOKUP(K21,'Interest, etc. BI and EF'!$A$2:$A$11,'Interest, etc. BI and EF'!$L$2:$L$11)/_xlfn.XLOOKUP($C21,'Interest, etc. BI and EF'!$A$2:$A$11,'Interest, etc. BI and EF'!$L$2:$L$11) -> 21313462 | L25: =$C25*_xlfn.XLOOKUP(L21,'Interest, etc. BI and EF'!$A$2:$A$11,'Interest, etc. BI and EF'!$L$2:$L$11)/_xlfn.XLOOKUP($C21,'Interest, etc. BI and EF'!$A$2:$A$11,'Interest, etc. BI and EF'!$L$2:$L$11) -> 22273340
B26: Profit at half year | C26: =C22+C23+C24-C25 -> -8428478.2 | D26: =D22+D23+D24-D25 -> -17414013 | E26: =E22+E23+E24-E25 -> -26985120 | F26: =F22+F23+F24-F25 -> -37169763 | G26: =G22+G23+G24-G25 -> -47996106 | H26: =H22+H23+H24-H25 -> -59492931 | I26: =I22+I23+I24-I25 -> -71689889 | J26: =J22+J23+J24-J25 -> -84617636 | ... L26: =L22+L23+L24-L25 -> -1.1279371e+08
B27: Interest on Profit | C27: =C26*((1+_xlfn.XLOOKUP(C$21,'Interest, etc. BI and EF'!$A$2:$A$11,'Interest, etc. BI and EF'!$C$2:$C$11))^(1/2)-1) -> -74433.016 | D27: =D26*((1+_xlfn.XLOOKUP(D$21,'Interest, etc. BI and EF'!$A$2:$A$11,'Interest, etc. BI and EF'!$C$2:$C$11))^(1/2)-1) -> -155011.34 | E27: =E26*((1+_xlfn.XLOOKUP(E$21,'Interest, etc. BI and EF'!$A$2:$A$11,'Interest, etc. BI and EF'!$C$2:$C$11))^(1/2)-1) -> -241332.71 | F27: =F26*((1+_xlfn.XLOOKUP(F$21,'Interest, etc. BI and EF'!$A$2:$A$11,'Interest, etc. BI and EF'!$C$2:$C$11))^(1/2)-1) -> -333331.69 | G27: =G26*((1+_xlfn.XLOOKUP(G$21,'Interest, etc. BI and EF'!$A$2:$A$11,'Interest, etc. BI and EF'!$C$2:$C$11))^(1/2)-1) -> -431120.11 | H27: =H26*((1+_xlfn.XLOOKUP(H$21,'Interest, etc. BI and EF'!$A$2:$A$11,'Interest, etc. BI and EF'!$C$2:$C$11))^(1/2)-1) -> -534902.36 | I27: =I26*((1+_xlfn.XLOOKUP(I$21,'Interest, etc. BI and EF'!$A$2:$A$11,'Interest, etc. BI and EF'!$C$2:$C$11))^(1/2)-1) -> -644931.37 | J27: =J26*((1+_xlfn.XLOOKUP(J$21,'Interest, etc. BI and EF'!$A$2:$A$11,'Interest, etc. BI and EF'!$C$2:$C$11))^(1/2)-1) -> -761486.52 | ... L27: =L26*((1+_xlfn.XLOOKUP(L$21,'Interest, etc. BI and EF'!$A$2:$A$11,'Interest, etc. BI and EF'!$C$2:$C$11))^(1/2)-1) -> -1015367.9
B28: Final Profit | C28: =C26+C27 -> -8502911.2 | D28: =D26+D27 -> -17569024 | E28: =E26+E27 -> -27226453 | F28: =F26+F27 -> -37503095 | G28: =G26+G27 -> -48427226 | H28: =H26+H27 -> -60027834 | I28: =I26+I27 -> -72334820 | J28: =J26+J27 -> -85379123 | ... L28: =L26+L27 -> -1.1380908e+08

Sheet Equipment Failure
A1: Equipment Failure
B2: Expected Costs | C2: 1 | D2: 2 | E2: 3 | F2: 4 | G2: 5 | H2: 6 | I2: 7 | J2: 8 | K2: 9 | L2: 10
B3: Retained Earnings | C3: 0 | D3: =C9 -> 2368923.4 | E3: =D9 -> 4887786.1 | F3: =E9 -> 7566610.7 | G3: =F9 -> 10414508 | H3: =G9 -> 13440163 | I3: =H9 -> 16652133 | J3: =I9 -> 20059023 | K3: =J9 -> 23669599 | L3: =K9 -> 27492859
B4: Premium Revenue (Inflation + Exposure) | C4: 108505130 | D4: =$C4*_xlfn.XLOOKUP(D2,'Interest, etc. BI and EF'!$A$2:$A$11,'Interest, etc. BI and EF'!$I$2:$I$11) -> 1.1372411e+08 | E4: =$C4*_xlfn.XLOOKUP(E2,'Interest, etc. BI and EF'!$A$2:$A$11,'Interest, etc. BI and EF'!$I$2:$I$11) -> 1.1916368e+08 | F4: =$C4*_xlfn.XLOOKUP(F2,'Interest, etc. BI and EF'!$A$2:$A$11,'Interest, etc. BI and EF'!$I$2:$I$11) -> 1.2482119e+08 | G4: =$C4*_xlfn.XLOOKUP(G2,'Interest, etc. BI and EF'!$A$2:$A$11,'Interest, etc. BI and EF'!$I$2:$I$11) -> 1.3069769e+08 | H4: =$C4*_xlfn.XLOOKUP(H2,'Interest, etc. BI and EF'!$A$2:$A$11,'Interest, etc. BI and EF'!$I$2:$I$11) -> 1.3679656e+08 | I4: =$C4*_xlfn.XLOOKUP(I2,'Interest, etc. BI and EF'!$A$2:$A$11,'Interest, etc. BI and EF'!$I$2:$I$11) -> 1.4312277e+08 | J4: =$C4*_xlfn.XLOOKUP(J2,'Interest, etc. BI and EF'!$A$2:$A$11,'Interest, etc. BI and EF'!$I$2:$I$11) -> 1.4968231e+08 | K4: =$C4*_xlfn.XLOOKUP(K2,'Interest, etc. BI and EF'!$A$2:$A$11,'Interest, etc. BI and EF'!$I$2:$I$11) -> 1.5648195e+08 | L4: =$C4*_xlfn.XLOOKUP(L2,'Interest, etc. BI and EF'!$A$2:$A$11,'Interest, etc. BI and EF'!$I$2:$I$11) -> 1.6352899e+08
A5: half of current year | B5: Interest on Premium and Retained Profits | C5: =(C3+C4)*((1+_xlfn.XLOOKUP(C$2,'Interest, etc. BI and EF'!$A$2:$A$11,'Interest, etc. BI and EF'!$C$2:$C$11))^(1/2)-1) -> 958223.29 | D5: =(D3+D4)*((1+_xlfn.XLOOKUP(D$2,'Interest, etc. BI and EF'!$A$2:$A$11,'Interest, etc. BI and EF'!$C$2:$C$11))^(1/2)-1) -> 1033405.5 | E5: =(E3+E4)*((1+_xlfn.XLOOKUP(E$2,'Interest, etc. BI and EF'!$A$2:$A$11,'Interest, etc. BI and EF'!$C$2:$C$11))^(1/2)-1) -> 1109414.2 | F5: =(F3+F4)*((1+_xlfn.XLOOKUP(F$2,'Interest, etc. BI and EF'!$A$2:$A$11,'Interest, etc. BI and EF'!$C$2:$C$11))^(1/2)-1) -> 1187229.8 | G5: =(G3+G4)*((1+_xlfn.XLOOKUP(G$2,'Interest, etc. BI and EF'!$A$2:$A$11,'Interest, etc. BI and EF'!$C$2:$C$11))^(1/2)-1) -> 1267525.9 | H5: =(H3+H4)*((1+_xlfn.XLOOKUP(H$2,'Interest, etc. BI and EF'!$A$2:$A$11,'Interest, etc. BI and EF'!$C$2:$C$11))^(1/2)-1) -> 1350782 | I5: =(I3+I4)*((1+_xlfn.XLOOKUP(I$2,'Interest, etc. BI and EF'!$A$2:$A$11,'Interest, etc. BI and EF'!$C$2:$C$11))^(1/2)-1) -> 1437355.4 | J5: =(J3+J4)*((1+_xlfn.XLOOKUP(J$2,'Interest, etc. BI and EF'!$A$2:$A$11,'Interest, etc. BI and EF'!$C$2:$C$11))^(1/2)-1) -> 1527527.2 | ... L5: =(L3+L4)*((1+_xlfn.XLOOKUP(L$2,'Interest, etc. BI and EF'!$A$2:$A$11,'Interest, etc. BI and EF'!$C$2:$C$11))^(1/2)-1) -> 1719576.9
A6: half previous year + half current year | B6: Costs (Inflation + Exposure) | C6: =105834251*_xlfn.XLOOKUP(C12,'Interest, etc. BI and EF'!$A$2:$A$11,'Interest, etc. BI and EF'!$L$2:$L$11) -> 1.0711517e+08 | D6: =$C6*_xlfn.XLOOKUP(D2,'Interest, etc. BI and EF'!$A$2:$A$11,'Interest, etc. BI and EF'!$L$2:$L$11)/_xlfn.XLOOKUP($C2,'Interest, etc. BI and EF'!$A$2:$A$11,'Interest, etc. BI and EF'!$L$2:$L$11) -> 1.1228178e+08 | E6: =$C6*_xlfn.XLOOKUP(E2,'Interest, etc. BI and EF'!$A$2:$A$11,'Interest, etc. BI and EF'!$L$2:$L$11)/_xlfn.XLOOKUP($C2,'Interest, etc. BI and EF'!$A$2:$A$11,'Interest, etc. BI and EF'!$L$2:$L$11) -> 1.1766134e+08 | F6: =$C6*_xlfn.XLOOKUP(F2,'Interest, etc. BI and EF'!$A$2:$A$11,'Interest, etc. BI and EF'!$L$2:$L$11)/_xlfn.XLOOKUP($C2,'Interest, etc. BI and EF'!$A$2:$A$11,'Interest, etc. BI and EF'!$L$2:$L$11) -> 1.2325309e+08 | G6: =$C6*_xlfn.XLOOKUP(G2,'Interest, etc. BI and EF'!$A$2:$A$11,'Interest, etc. BI and EF'!$L$2:$L$11)/_xlfn.XLOOKUP($C2,'Interest, etc. BI and EF'!$A$2:$A$11,'Interest, etc. BI and EF'!$L$2:$L$11) -> 1.2905921e+08 | H6: =$C6*_xlfn.XLOOKUP(H2,'Interest, etc. BI and EF'!$A$2:$A$11,'Interest, etc. BI and EF'!$L$2:$L$11)/_xlfn.XLOOKUP($C2,'Interest, etc. BI and EF'!$A$2:$A$11,'Interest, etc. BI and EF'!$L$2:$L$11) -> 1.3508376e+08 | I6: =$C6*_xlfn.XLOOKUP(I2,'Interest, etc. BI and EF'!$A$2:$A$11,'Interest, etc. BI and EF'!$L$2:$L$11)/_xlfn.XLOOKUP($C2,'Interest, etc. BI and EF'!$A$2:$A$11,'Interest, etc. BI and EF'!$L$2:$L$11) -> 1.4133208e+08 | J6: =$C6*_xlfn.XLOOKUP(J2,'Interest, etc. BI and EF'!$A$2:$A$11,'Interest, etc. BI and EF'!$L$2:$L$11)/_xlfn.XLOOKUP($C2,'Interest, etc. BI and EF'!$A$2:$A$11,'Interest, etc. BI and EF'!$L$2:$L$11) -> 1.4781037e+08 | K6: =$C6*_xlfn.XLOOKUP(K2,'Interest, etc. BI and EF'!$A$2:$A$11,'Interest, etc. BI and EF'!$L$2:$L$11)/_xlfn.XLOOKUP($C2,'Interest, etc. BI and EF'!$A$2:$A$11,'Interest, etc. BI and EF'!$L$2:$L$11) -> 1.5452548e+08 | L6: =$C6*_xlfn.XLOOKUP(L2,'Interest, etc. BI and EF'!$A$2:$A$11,'Interest, etc. BI and EF'!$L$2:$L$11)/_xlfn.XLOOKUP($C2,'Interest, etc. BI and EF'!$A$2:$A$11,'Interest, etc. BI and EF'!$L$2:$L$11) -> 1.6148472e+08
B7: Profit at half year | C7: =C3+C4+C5-C6 -> 2348186.3 | D7: =D3+D4+D5-D6 -> 4844661.2 | E7: =E3+E4+E5-E6 -> 7499541 | F7: =F3+F4+F5-F6 -> 10321942 | G7: =G3+G4+G5-G6 -> 13320513 | H7: =H3+H4+H5-H6 -> 16503748 | I7: =I3+I4+I5-I6 -> 19880179 | J7: =J3+J4+J5-J6 -> 23458493 | ... L7: =L3+L4+L5-L6 -> 31256705
B8: Interest on Profit | C8: =C7*((1+_xlfn.XLOOKUP(C$2,'Interest, etc. BI and EF'!$A$2:$A$11,'Interest, etc. BI and EF'!$C$2:$C$11))^(1/2)-1) -> 20737.146 | D8: =D7*((1+_xlfn.XLOOKUP(D$2,'Interest, etc. BI and EF'!$A$2:$A$11,'Interest, etc. BI and EF'!$C$2:$C$11))^(1/2)-1) -> 43124.892 | E8: =E7*((1+_xlfn.XLOOKUP(E$2,'Interest, etc. BI and EF'!$A$2:$A$11,'Interest, etc. BI and EF'!$C$2:$C$11))^(1/2)-1) -> 67069.725 | F8: =F7*((1+_xlfn.XLOOKUP(F$2,'Interest, etc. BI and EF'!$A$2:$A$11,'Interest, etc. BI and EF'!$C$2:$C$11))^(1/2)-1) -> 92565.308 | G8: =G7*((1+_xlfn.XLOOKUP(G$2,'Interest, etc. BI and EF'!$A$2:$A$11,'Interest, etc. BI and EF'!$C$2:$C$11))^(1/2)-1) -> 119650.15 | H8: =H7*((1+_xlfn.XLOOKUP(H$2,'Interest, etc. BI and EF'!$A$2:$A$11,'Interest, etc. BI and EF'!$C$2:$C$11))^(1/2)-1) -> 148385.59 | I8: =I7*((1+_xlfn.XLOOKUP(I$2,'Interest, etc. BI and EF'!$A$2:$A$11,'Interest, etc. BI and EF'!$C$2:$C$11))^(1/2)-1) -> 178844.62 | J8: =J7*((1+_xlfn.XLOOKUP(J$2,'Interest, etc. BI and EF'!$A$2:$A$11,'Interest, etc. BI and EF'!$C$2:$C$11))^(1/2)-1) -> 211106.42 | ... L8: =L7*((1+_xlfn.XLOOKUP(L$2,'Interest, etc. BI and EF'!$A$2:$A$11,'Interest, etc. BI and EF'!$C$2:$C$11))^(1/2)-1) -> 281372.56
B9: Final Profit | C9: =C7+C8 -> 2368923.4 | D9: =D7+D8 -> 4887786.1 | E9: =E7+E8 -> 7566610.7 | F9: =F7+F8 -> 10414508 | G9: =G7+G8 -> 13440163 | H9: =H7+H8 -> 16652133 | I9: =I7+I8 -> 20059023 | J9: =J7+J8 -> 23669599 | ... L9: =L7+L8 -> 31538077
B12: Lower Bound | C12: 1 | D12: 2 | E12: 3 | F12: 4 | G12: 5 | H12: 6 | I12: 7 | J12: 8 | K12: 9 | L12: 10
B13: Retained Earnings | C13: 0 | D13: =C19 -> 9316398.2 | E13: =D19 -> 19242586 | F13: =E19 -> 29811659 | G13: =F19 -> 41055586 | H13: =G19 -> 53006192 | I13: =H19 -> 65695741 | J13: =I19 -> 79157283 | K13: =J19 -> 93424870 | L13: =K19 -> 1.0853369e+08
B14: Premium Revenue (Inflation + Exposure) | C14: 108505130 | D14: =$C14*_xlfn.XLOOKUP(D12,'Interest, etc. BI and EF'!$A$2:$A$11,'Interest, etc. BI and EF'!$I$2:$I$11) -> 1.1372411e+08 | E14: =$C14*_xlfn.XLOOKUP(E12,'Interest, etc. BI and EF'!$A$2:$A$11,'Interest, etc. BI and EF'!$I$2:$I$11) -> 1.1916368e+08 | F14: =$C14*_xlfn.XLOOKUP(F12,'Interest, etc. BI and EF'!$A$2:$A$11,'Interest, etc. BI and EF'!$I$2:$I$11) -> 1.2482119e+08 | G14: =$C14*_xlfn.XLOOKUP(G12,'Interest, etc. BI and EF'!$A$2:$A$11,'Interest, etc. BI and EF'!$I$2:$I$11) -> 1.3069769e+08 | H14: =$C14*_xlfn.XLOOKUP(H12,'Interest, etc. BI and EF'!$A$2:$A$11,'Interest, etc. BI and EF'!$I$2:$I$11) -> 1.3679656e+08 | I14: =$C14*_xlfn.XLOOKUP(I12,'Interest, etc. BI and EF'!$A$2:$A$11,'Interest, etc. BI and EF'!$I$2:$I$11) -> 1.4312277e+08 | J14: =$C14*_xlfn.XLOOKUP(J12,'Interest, etc. BI and EF'!$A$2:$A$11,'Interest, etc. BI and EF'!$I$2:$I$11) -> 1.4968231e+08 | K14: =$C14*_xlfn.XLOOKUP(K12,'Interest, etc. BI and EF'!$A$2:$A$11,'Interest, etc. BI and EF'!$I$2:$I$11) -> 1.5648195e+08 | L14: =$C14*_xlfn.XLOOKUP(L12,'Interest, etc. BI and EF'!$A$2:$A$11,'Interest, etc. BI and EF'!$I$2:$I$11) -> 1.6352899e+08
A15: half of current year | B15: Interest on Premium and Retained Profits | C15: =(C13+C14)*((1+_xlfn.XLOOKUP(C$12,'Interest, etc. BI and EF'!$A$2:$A$11,'Interest, etc. BI and EF'!$C$2:$C$11))^(1/2)-1) -> 958223.29 | D15: =(D13+D14)*((1+_xlfn.XLOOKUP(D$12,'Interest, etc. BI and EF'!$A$2:$A$11,'Interest, etc. BI and EF'!$C$2:$C$11))^(1/2)-1) -> 1095248.6 | E15: =(E13+E14)*((1+_xlfn.XLOOKUP(E$12,'Interest, etc. BI and EF'!$A$2:$A$11,'Interest, etc. BI and EF'!$C$2:$C$11))^(1/2)-1) -> 1237791.8 | F15: =(F13+F14)*((1+_xlfn.XLOOKUP(F$12,'Interest, etc. BI and EF'!$A$2:$A$11,'Interest, etc. BI and EF'!$C$2:$C$11))^(1/2)-1) -> 1386719.4 | G15: =(G13+G14)*((1+_xlfn.XLOOKUP(G$12,'Interest, etc. BI and EF'!$A$2:$A$11,'Interest, etc. BI and EF'!$C$2:$C$11))^(1/2)-1) -> 1542756.2 | H15: =(H13+H14)*((1+_xlfn.XLOOKUP(H$12,'Interest, etc. BI and EF'!$A$2:$A$11,'Interest, etc. BI and EF'!$C$2:$C$11))^(1/2)-1) -> 1706521.1 | I15: =(I13+I14)*((1+_xlfn.XLOOKUP(I$12,'Interest, etc. BI and EF'!$A$2:$A$11,'Interest, etc. BI and EF'!$C$2:$C$11))^(1/2)-1) -> 1878557.9 | J15: =(J13+J14)*((1+_xlfn.XLOOKUP(J$12,'Interest, etc. BI and EF'!$A$2:$A$11,'Interest, etc. BI and EF'!$C$2:$C$11))^(1/2)-1) -> 2059361.1 | ... L15: =(L13+L14)*((1+_xlfn.XLOOKUP(L$12,'Interest, etc. BI and EF'!$A$2:$A$11,'Interest, etc. BI and EF'!$C$2:$C$11))^(1/2)-1) -> 2449105.7
